<?xml version="1.0" ?>
<!-- =================================================================================== -->
<!-- |    This document was autogenerated by xacro from kkbot.urdf.xacro               | -->
<!-- |    EDITING THIS FILE BY HAND IS NOT RECOMMENDED                                 | -->
<!-- =================================================================================== -->
<robot name="kkbot">
  <!-- base_footprint -->
  <link name="base_footprint"/>
  <!-- base -->
  <link name="base_link">
    <visual>
      <origin rpy="0 0 0" xyz="0 0 0"/>
      <geometry>
        <cylinder length="0.12" radius="0.1"/>
      </geometry>
      <material name="blue">
        <color rgba="0.0 0.0 0.8 0.5"/>
      </material>
    </visual>
    <collision>
      <origin rpy="0 0 0" xyz="0 0 0"/>
      <geometry>
        <cylinder length="0.12" radius="0.1"/>
      </geometry>
      <material name="blue">
        <color rgba="0.0 0.0 0.8 0.5"/>
      </material>
    </collision>
    <inertial>
      <origin rpy="1.5707963267948966 0 0" xyz="0 0 0"/>
      <mass value="0.2"/>
      <inertia ixx="0.0007400000000000001" ixy="0" ixz="0" iyy="0.0007400000000000001" iyz="0" izz="0.0010000000000000002"/>
    </inertial>
  </link>
  <joint name="base_joint" type="fixed">
    <parent link="base_footprint"/>
    <child link="base_link"/>
    <origin xyz="0 0 0.092"/>
    <axis xyz="0 0 0"/>
  </joint>
  <!-- laser -->
  <link name="laser_link">
    <visual>
      <origin rpy="0 0 0" xyz="0 0 0"/>
      <geometry>
        <cylinder length="0.02" radius="0.02"/>
      </geometry>
      <material name="red">
        <color rgba="0.8 0.0 0.0 0.5"/>
      </material>
    </visual>
    <collision>
      <origin rpy="0 0 0" xyz="0 0 0"/>
      <geometry>
        <cylinder length="0.02" radius="0.02"/>
      </geometry>
      <material name="red">
        <color rgba="0.8 0.0 0.0 0.5"/>
      </material>
    </collision>
    <inertial>
      <origin rpy="1.5707963267948966 0 0" xyz="0 0 0"/>
      <mass value="0.1"/>
      <inertia ixx="1.3333333333333332e-05" ixy="0" ixz="0" iyy="1.3333333333333332e-05" iyz="0" izz="2e-05"/>
    </inertial>
  </link>
  <joint name="laser_joint" type="fixed">
    <parent link="base_link"/>
    <child link="laser_link"/>
    <origin xyz="0 0 0.075"/>
    <axis xyz="0 0 0"/>
  </joint>
  <!-- imu -->
  <link name="imu_link">
    <visual>
      <origin rpy="0 0 0" xyz="0 0 0"/>
      <geometry>
        <box size="0.02 0.02 0.02"/>
      </geometry>
      <material name="green">
        <color rgba="0.0 0.8 0.0 0.5"/>
      </material>
    </visual>
    <collision>
      <origin rpy="0 0 0" xyz="0 0 0"/>
      <geometry>
        <box size="0.02 0.02 0.02"/>
      </geometry>
      <material name="green">
        <color rgba="0.0 0.8 0.0 0.5"/>
      </material>
    </collision>
    <inertial>
      <origin rpy="1.5707963267948966 0 1.5707963267948966" xyz="0 0 0"/>
      <mass value="0.1"/>
      <inertia ixx="6.666666666666667e-06" ixy="0.0" ixz="0.0" iyy="6.666666666666667e-06" iyz="0.0" izz="6.666666666666667e-06"/>
    </inertial>
  </link>
  <joint name="imu_joint" type="fixed">
    <parent link="base_link"/>
    <child link="imu_link"/>
    <origin xyz="0 0 0.02"/>
    <axis xyz="0 0 0"/>
  </joint>
  <!-- left_wheel -->
  <link name="left_wheel_link">
    <visual>
      <origin rpy="1.5707963267948966 0 0" xyz="0 0 0"/>
      <geometry>
        <cylinder length="0.04" radius="0.032"/>
      </geometry>
      <material name="black">
        <color rgba="0.0 0.0 0.0 0.5"/>
      </material>
    </visual>
    <collision>
      <origin rpy="1.5707963267948966 0 0" xyz="0 0 0"/>
      <geometry>
        <cylinder length="0.04" radius="0.032"/>
      </geometry>
      <material name="black">
        <color rgba="0.0 0.0 0.0 0.5"/>
      </material>
    </collision>
    <inertial>
      <origin rpy="1.5707963267948966 0 0" xyz="0 0 0"/>
      <mass value="0.2"/>
      <inertia ixx="7.786666666666667e-05" ixy="0" ixz="0" iyy="7.786666666666667e-05" iyz="0" izz="0.0001024"/>
    </inertial>
  </link>
  <joint name="left_wheel_joint" type="continuous">
    <parent link="base_link"/>
    <child link="left_wheel_link"/>
    <origin xyz="-0.02 0.1 -0.06"/>
    <axis xyz="0 1 0"/>
  </joint>
  <!-- right_wheel -->
  <link name="right_wheel_link">
    <visual>
      <origin rpy="1.5707963267948966 0 0" xyz="0 0 0"/>
      <geometry>
        <cylinder length="0.04" radius="0.032"/>
      </geometry>
      <material name="black">
        <color rgba="0.0 0.0 0.0 0.5"/>
      </material>
    </visual>
    <collision>
      <origin rpy="1.5707963267948966 0 0" xyz="0 0 0"/>
      <geometry>
        <cylinder length="0.04" radius="0.032"/>
      </geometry>
      <material name="black">
        <color rgba="0.0 0.0 0.0 0.5"/>
      </material>
    </collision>
    <inertial>
      <origin rpy="1.5707963267948966 0 0" xyz="0 0 0"/>
      <mass value="0.2"/>
      <inertia ixx="7.786666666666667e-05" ixy="0" ixz="0" iyy="7.786666666666667e-05" iyz="0" izz="0.0001024"/>
    </inertial>
  </link>
  <joint name="right_wheel_joint" type="continuous">
    <parent link="base_link"/>
    <child link="right_wheel_link"/>
    <origin xyz="-0.02 -0.1 -0.06"/>
    <axis xyz="0 1 0"/>
  </joint>
  <!-- caster -->
  <link name="caster_link">
    <visual>
      <origin rpy="0 0 0" xyz="0 0 0"/>
      <geometry>
        <sphere radius="0.016"/>
      </geometry>
      <material name="white">
        <color rgba="1 1 1 0.5"/>
      </material>
    </visual>
    <collision>
      <origin rpy="0 0 0" xyz="0 0 0"/>
      <geometry>
        <sphere radius="0.016"/>
      </geometry>
      <material name="white">
        <color rgba="1 1 1 0.5"/>
      </material>
    </collision>
    <inertial>
      <mass value="0.02"/>
      <inertia ixx="2.048e-06" ixy="0.0" ixz="0.0" iyy="2.048e-06" iyz="0.0" izz="2.048e-06"/>
    </inertial>
  </link>
  <joint name="caster_joint" type="fixed">
    <parent link="base_link"/>
    <child link="caster_link"/>
    <origin xyz="0.06 0 -0.076"/>
    <axis xyz="0 1 0"/>
  </joint>
</robot>
